Using **std::nothrow** with new is supposed to stop **new** from throwing exception but it seems not to be working for me and new throws exception anyway.  
Well I'm going to fix this practice as soon as I understand the cause of it.
