Exception caught in main: An exception
No exception was thrown!
